<?xml version="1.0" encoding="UTF-8"?>
<testng-results ignored="0" total="3" passed="1" failed="2" skipped="0">
  <reporter-output>
  </reporter-output>
  <suite started-at="2023-12-17T15:32:33 IST" name="Default suite" finished-at="2023-12-17T15:33:56 IST" duration-ms="83603">
    <groups>
    </groups>
    <test started-at="2023-12-17T15:32:33 IST" name="Default test" finished-at="2023-12-17T15:33:56 IST" duration-ms="83603">
      <class name="testCases.testLogin">
        <test-method is-config="true" signature="beforeMethod()[pri:0, instance:testCases.testLogin@6a192cfe]" started-at="2023-12-17T15:32:33 IST" name="beforeMethod" finished-at="2023-12-17T15:32:56 IST" duration-ms="22850" status="PASS">
          <reporter-output>
          </reporter-output>
        </test-method> <!-- beforeMethod -->
        <test-method signature="a()[pri:0, instance:testCases.testLogin@6a192cfe]" started-at="2023-12-17T15:32:56 IST" name="a" finished-at="2023-12-17T15:33:06 IST" duration-ms="10057" status="FAIL">
          <exception class="java.lang.AssertionError">
            <message>
              <![CDATA[Unabe to Login expected [false] but found [true]]]>
            </message>
            <full-stacktrace>
              <![CDATA[java.lang.AssertionError: Unabe to Login expected [false] but found [true]
at org.testng.Assert.fail(Assert.java:99)
at org.testng.Assert.failNotEquals(Assert.java:1037)
at org.testng.Assert.assertFalse(Assert.java:67)
at Pages.Cart.test(Cart.java:58)
at testCases.testLogin.a(testLogin.java:28)
at java.base/jdk.internal.reflect.DirectMethodHandleAccessor.invoke(DirectMethodHandleAccessor.java:104)
at java.base/java.lang.reflect.Method.invoke(Method.java:578)
at org.testng.internal.MethodInvocationHelper.invokeMethod(MethodInvocationHelper.java:133)
at org.testng.internal.TestInvoker.invokeMethod(TestInvoker.java:598)
at org.testng.internal.TestInvoker.invokeTestMethod(TestInvoker.java:173)
at org.testng.internal.MethodRunner.runInSequence(MethodRunner.java:46)
at org.testng.internal.TestInvoker$MethodInvocationAgent.invoke(TestInvoker.java:824)
at org.testng.internal.TestInvoker.invokeTestMethods(TestInvoker.java:146)
at org.testng.internal.TestMethodWorker.invokeTestMethods(TestMethodWorker.java:146)
at org.testng.internal.TestMethodWorker.run(TestMethodWorker.java:128)
at java.base/java.util.ArrayList.forEach(ArrayList.java:1511)
at org.testng.TestRunner.privateRun(TestRunner.java:794)
at org.testng.TestRunner.run(TestRunner.java:596)
at org.testng.SuiteRunner.runTest(SuiteRunner.java:377)
at org.testng.SuiteRunner.runSequentially(SuiteRunner.java:371)
at org.testng.SuiteRunner.privateRun(SuiteRunner.java:332)
at org.testng.SuiteRunner.run(SuiteRunner.java:276)
at org.testng.SuiteRunnerWorker.runSuite(SuiteRunnerWorker.java:53)
at org.testng.SuiteRunnerWorker.run(SuiteRunnerWorker.java:96)
at org.testng.TestNG.runSuitesSequentially(TestNG.java:1212)
at org.testng.TestNG.runSuitesLocally(TestNG.java:1134)
at org.testng.TestNG.runSuites(TestNG.java:1063)
at org.testng.TestNG.run(TestNG.java:1031)
at org.testng.remote.AbstractRemoteTestNG.run(AbstractRemoteTestNG.java:115)
at org.testng.remote.RemoteTestNG.initAndRun(RemoteTestNG.java:251)
at org.testng.remote.RemoteTestNG.main(RemoteTestNG.java:77)
]]>
            </full-stacktrace>
          </exception> <!-- java.lang.AssertionError -->
          <reporter-output>
          </reporter-output>
        </test-method> <!-- a -->
        <test-method is-config="true" signature="afterMethod()[pri:0, instance:testCases.testLogin@6a192cfe]" started-at="2023-12-17T15:33:06 IST" name="afterMethod" finished-at="2023-12-17T15:33:06 IST" duration-ms="2" status="PASS">
          <reporter-output>
          </reporter-output>
        </test-method> <!-- afterMethod -->
        <test-method is-config="true" signature="beforeMethod()[pri:0, instance:testCases.testLogin@6a192cfe]" started-at="2023-12-17T15:33:06 IST" name="beforeMethod" finished-at="2023-12-17T15:33:21 IST" duration-ms="15522" status="PASS">
          <reporter-output>
          </reporter-output>
        </test-method> <!-- beforeMethod -->
        <test-method signature="b()[pri:0, instance:testCases.testLogin@6a192cfe]" started-at="2023-12-17T15:33:21 IST" name="b" finished-at="2023-12-17T15:33:30 IST" duration-ms="9011" status="FAIL">
          <exception class="java.lang.AssertionError">
            <message>
              <![CDATA[Unabe to Login expected [false] but found [true]]]>
            </message>
            <full-stacktrace>
              <![CDATA[java.lang.AssertionError: Unabe to Login expected [false] but found [true]
at org.testng.Assert.fail(Assert.java:99)
at org.testng.Assert.failNotEquals(Assert.java:1037)
at org.testng.Assert.assertFalse(Assert.java:67)
at Pages.Cart.test(Cart.java:58)
at testCases.testLogin.b(testLogin.java:33)
at java.base/jdk.internal.reflect.DirectMethodHandleAccessor.invoke(DirectMethodHandleAccessor.java:104)
at java.base/java.lang.reflect.Method.invoke(Method.java:578)
at org.testng.internal.MethodInvocationHelper.invokeMethod(MethodInvocationHelper.java:133)
at org.testng.internal.TestInvoker.invokeMethod(TestInvoker.java:598)
at org.testng.internal.TestInvoker.invokeTestMethod(TestInvoker.java:173)
at org.testng.internal.MethodRunner.runInSequence(MethodRunner.java:46)
at org.testng.internal.TestInvoker$MethodInvocationAgent.invoke(TestInvoker.java:824)
at org.testng.internal.TestInvoker.invokeTestMethods(TestInvoker.java:146)
at org.testng.internal.TestMethodWorker.invokeTestMethods(TestMethodWorker.java:146)
at org.testng.internal.TestMethodWorker.run(TestMethodWorker.java:128)
at java.base/java.util.ArrayList.forEach(ArrayList.java:1511)
at org.testng.TestRunner.privateRun(TestRunner.java:794)
at org.testng.TestRunner.run(TestRunner.java:596)
at org.testng.SuiteRunner.runTest(SuiteRunner.java:377)
at org.testng.SuiteRunner.runSequentially(SuiteRunner.java:371)
at org.testng.SuiteRunner.privateRun(SuiteRunner.java:332)
at org.testng.SuiteRunner.run(SuiteRunner.java:276)
at org.testng.SuiteRunnerWorker.runSuite(SuiteRunnerWorker.java:53)
at org.testng.SuiteRunnerWorker.run(SuiteRunnerWorker.java:96)
at org.testng.TestNG.runSuitesSequentially(TestNG.java:1212)
at org.testng.TestNG.runSuitesLocally(TestNG.java:1134)
at org.testng.TestNG.runSuites(TestNG.java:1063)
at org.testng.TestNG.run(TestNG.java:1031)
at org.testng.remote.AbstractRemoteTestNG.run(AbstractRemoteTestNG.java:115)
at org.testng.remote.RemoteTestNG.initAndRun(RemoteTestNG.java:251)
at org.testng.remote.RemoteTestNG.main(RemoteTestNG.java:77)
]]>
            </full-stacktrace>
          </exception> <!-- java.lang.AssertionError -->
          <reporter-output>
          </reporter-output>
        </test-method> <!-- b -->
        <test-method is-config="true" signature="afterMethod()[pri:0, instance:testCases.testLogin@6a192cfe]" started-at="2023-12-17T15:33:30 IST" name="afterMethod" finished-at="2023-12-17T15:33:30 IST" duration-ms="1" status="PASS">
          <reporter-output>
          </reporter-output>
        </test-method> <!-- afterMethod -->
        <test-method is-config="true" signature="beforeMethod()[pri:0, instance:testCases.testLogin@6a192cfe]" started-at="2023-12-17T15:33:30 IST" name="beforeMethod" finished-at="2023-12-17T15:33:45 IST" duration-ms="14513" status="PASS">
          <reporter-output>
          </reporter-output>
        </test-method> <!-- beforeMethod -->
        <test-method signature="c()[pri:0, instance:testCases.testLogin@6a192cfe]" started-at="2023-12-17T15:33:45 IST" name="c" finished-at="2023-12-17T15:33:56 IST" duration-ms="11547" status="PASS">
          <reporter-output>
          </reporter-output>
        </test-method> <!-- c -->
        <test-method is-config="true" signature="afterMethod()[pri:0, instance:testCases.testLogin@6a192cfe]" started-at="2023-12-17T15:33:56 IST" name="afterMethod" finished-at="2023-12-17T15:33:56 IST" duration-ms="0" status="PASS">
          <reporter-output>
          </reporter-output>
        </test-method> <!-- afterMethod -->
      </class> <!-- testCases.testLogin -->
    </test> <!-- Default test -->
  </suite> <!-- Default suite -->
</testng-results>
